Workbook

Sheet 📌 Instructions
A1: Make a copy of this spreadsheet before using. | B1: 📝 A2 Lithuanian Vocabulary Self-Assessment Test
B3: HOW TO USE THIS TEST:
B5: 1. Go to the "Vocabulary Test" sheet
B6: 2. Filter "Tier" column for Tier 1
B7: 2. Read each Lithuanian word
B8: 3. In the "Know It?" column, select from dropdown:
B9: ✓ = I know this word confidently
B10: ? = I think I know it / not sure
B11: ✗ = I don't know this word
B12: 4. (Optional) Write the English translation in the "My Translation" column
B13: 5. Repeat the process for Tier 2, 3 and 4
B14: 6. Go to the "Results" sheet to see your score!
B16: 💡 TIPS:
... B35: Ready? Let's test your Lithuanian vocabulary! →

Sheet 📝 Vocabulary Test
B1: # | C1: Lithuanian Word | D1: Topic | E1: Tier | F1: Know It? | G1: My Translation | H1: Instructions
B2: 1 | C2: vardas | D2: Asmens tapatybė | E2: Tier 1 | F2: ✓ | G2: name | H2: ✓ = I know this word confidently
B3: 2 | C3: pavardė | D3: Asmens tapatybė | E3: Tier 1 | F3: ? | G3: surname | H3: ? = I think I know it / not sure
B4: 3 | C4: adresas | D4: Asmens tapatybė | E4: Tier 1 | F4: ✓ | G4: address | H4: ✗ = I don't know this word
B5: 4 | C5: telefonas | D5: Asmens tapatybė | E5: Tier 1 | F5: ✓ | G5: tel no
B6: 5 | C6: amžius | D6: Asmens tapatybė | E6: Tier 1 | F6: ? | G6: age
B7: 6 | C7: tautybė | D7: Asmens tapatybė | E7: Tier 1 | F7: ? | G7: nationality
B8: 7 | C8: gyventi | D8: Asmens tapatybė | E8: Tier 1 | F8: ✓ | G8: place where you live
B9: 8 | C9: būti | D9: Asmens tapatybė | E9: Tier 1 | F9: ✓ | G9: to be
B10: 9 | C10: dirbti | D10: Asmens tapatybė | E10: Tier 1 | F10: ✓ | G10: to work
B11: 10 | C11: mokytis | D11: Asmens tapatybė | E11: Tier 1 | F11: ? | G11: to learn / to teach?
B12: 11 | C12: tėvas | D12: Asmens tapatybė | E12: Tier 1 | F12: ? | G12: father
B13: 12 | C13: motina | D13: Asmens tapatybė | E13: Tier 1 | F13: ? | G13: mother
B14: 13 | C14: brolis | D14: Asmens tapatybė | E14: Tier 1 | F14: ✓ | G14: brother
B15: 14 | C15: sesuo | D15: Asmens tapatybė | E15: Tier 1 | F15: ✓ | G15: sister
B16: 15 | C16: šeima | D16: Asmens tapatybė | E16: Tier 1 | F16: ✓ | G16: family
... B60: 59 | C60: kasa | D60: Asmens tapatybė | E60: Tier 3 | F60: ✓ | G60: cash desk
B61: 60 | C61: barzda | D61: Asmens tapatybė | E61: Tier 3 | F61: ✗
B62: 61 | C62: ūsai | D62: Asmens tapatybė | E62: Tier 3 | F62: ✓ | G62: moustache
B63: 62 | C63: akiniai | D63: Asmens tapatybė | E63: Tier 3 | F63: ✓ | G63: glasses
B64: 63 | C64: tinginys | D64: Asmens tapatybė | E64: Tier 3 | F64: ✓ | G64: lazy
B65: 64 | C65: piktas | D65: Asmens tapatybė | E65: Tier 3 | F65: ✓ | G65: angry
B66: 65 | C66: švelnus | D66: Asmens tapatybė | E66: Tier 3 | F66: ✓ | G66: gentle
B67: 66 | C67: įdomus | D67: Asmens tapatybė | E67: Tier 3 | F67: ✓ | G67: interesting
B68: 67 | C68: pavadinimai | D68: Asmens tapatybė | E68: Tier 4 | F68: ✗ | G68: to be called / name?
B69: 68 | C69: ypatybės | D69: Asmens tapatybė | E69: Tier 4 | F69: ✗
B70: 69 | C70: bruožai | D70: Asmens tapatybė | E70: Tier 4 | F70: ✗
B71: 70 | C71: mobilusis | D71: Asmens tapatybė | E71: Tier 4 | F71: ✗ | G71: mobile?
B72: 71 | C72: paraidžiui | D72: Asmens tapatybė | E72: Tier 4 | F72: ✗
B73: 72 | C73: šeiminė padėtis | D73: Asmens tapatybė | E73: Tier 4 | F73: ✗ | G73: family help? nanny perhaps?
B74: 73 | C74: namas | D74: Būstas | E74: Tier 1 | F74: ✓ | G74: home / house
B75: 74 | C75: butas | D75: Būstas | E75: Tier 1 | F75: ✓ | G75: flat
B76: 75 | C76: kambarys | D76: Būstas | E76: Tier 1 | F76: ✓ | G76: room
B77: 76 | C77: virtuvė | D77: Būstas | E77: Tier 1 | F77: ✓ | G77: kitchen
B78: 77 | C78: vonia | D78: Būstas | E78: Tier 1 | F78: ✓ | G78: bathroom
B79: 78 | C79: tualetas | D79: Būstas | E79: Tier 1 | F79: ✓ | G79: toilet
B80: 79 | C80: stalas | D80: Būstas | E80: Tier 1 | F80: ✓ | G80: table
B81: 80 | C81: kėdė | D81: Būstas | E81: Tier 1 | F81: ✓ | G81: chair
B82: 81 | C82: lova | D82: Būstas | E82: Tier 1 | F82: ? | G82: bed
B83: 82 | C83: spinta | D83: Būstas | E83: Tier 1 | F83: ✓ | G83: cupboard
...

Sheet 📊 Results
B2: Your Vocabulary Test Results
B4: Overall Score
B6: Total Words in Test: | C6: 874
B7: Words You Know (✓): | C7: =COUNTIF('📝 Vocabulary Test'!F:F,"✓") -> 484
B8: Words You're Unsure (?): | C8: =COUNTIF('📝 Vocabulary Test'!$F$2:$F$875,"~?") -> 204
B9: Words You Don't Know (✗): | C9: =COUNTIF('📝 Vocabulary Test'!F:F,"✗") -> 186
B10: Not Yet Tested: | C10: =874-COUNTA('📝 Vocabulary Test'!F2:F875) -> 0
B12: Knowledge Score: | C12: =IF(C7=0,"0%",C7/C6) -> 0.55377574
B18: Words by Topic
B19: Topic | C19: Total | D19: Know (✓) | E19: Unsure (?) | F19: Don't Know (✗) | G19: % Known
B20: Asmens tapatybė | C20: =COUNTIF('📝 Vocabulary Test'!D:D,"Asmens tapatybė") -> 72 | D20: =COUNTIFS('📝 Vocabulary Test'!D:D,"Asmens tapatybė",'📝 Vocabulary Test'!F:F,"✓") -> 37 | E20: =COUNTIFS('📝 Vocabulary Test'!$D$2:$D$875,"Asmens tapatybė",'📝 Vocabulary Test'!$F$2:$F$875,"~?") -> 21 | F20: =COUNTIFS('📝 Vocabulary Test'!$D$2:$D$875,"Asmens tapatybė",'📝 Vocabulary Test'!$F$2:$F$875,"✗") -> 14 | G20: =IF(C20=0,"0%",D20/C20) -> 0.51388889
B21: Būstas | C21: =COUNTIF('📝 Vocabulary Test'!D:D,"Būstas") -> 66 | D21: =COUNTIFS('📝 Vocabulary Test'!$D$2:$D$875,"Būstas",'📝 Vocabulary Test'!$F$2:$F$875,"✓") -> 36 | E21: =COUNTIFS('📝 Vocabulary Test'!$D$2:$D$875,"Būstas",'📝 Vocabulary Test'!$F$2:$F$875,"~?") -> 18 | F21: =COUNTIFS('📝 Vocabulary Test'!$D$2:$D$875,"Būstas",'📝 Vocabulary Test'!$F$2:$F$875,"✗") -> 12 | G21: =IF(C21=0,"0%",D21/C21) -> 0.54545455
B22: Gamta.Regionas | C22: =COUNTIF('📝 Vocabulary Test'!D:D,"Gamta.Regionas") -> 67 | D22: =COUNTIFS('📝 Vocabulary Test'!$D$2:$D$875,"Gamta.Regionas",'📝 Vocabulary Test'!$F$2:$F$875,"✓") -> 39 | E22: =COUNTIFS('📝 Vocabulary Test'!$D$2:$D$875,"Gamta.Regionas",'📝 Vocabulary Test'!$F$2:$F$875,"~?") -> 20 | F22: =COUNTIFS('📝 Vocabulary Test'!$D$2:$D$875,"Gamta.Regionas",'📝 Vocabulary Test'!$F$2:$F$875,"✗") -> 8 | G22: =IF(C22=0,"0%",D22/C22) -> 0.58208955
B23: Kasdienis gyvenimas | C23: =COUNTIF('📝 Vocabulary Test'!D:D,"Kasdienis gyvenimas") -> 80 | D23: =COUNTIFS('📝 Vocabulary Test'!$D$2:$D$875,"Kasdienis gyvenimas",'📝 Vocabulary Test'!$F$2:$F$875,"✓") -> 42 | E23: =COUNTIFS('📝 Vocabulary Test'!$D$2:$D$875,"Kasdienis gyvenimas",'📝 Vocabulary Test'!$F$2:$F$875,"~?") -> 18 | F23: =COUNTIFS('📝 Vocabulary Test'!$D$2:$D$875,"Kasdienis gyvenimas",'📝 Vocabulary Test'!$F$2:$F$875,"✗") -> 20 | G23: =IF(C23=0,"0%",D23/C23) -> 0.525
B24: Kelionės | C24: =COUNTIF('📝 Vocabulary Test'!D:D,"Kelionės") -> 69 | D24: =COUNTIFS('📝 Vocabulary Test'!$D$2:$D$875,"Kelionės",'📝 Vocabulary Test'!$F$2:$F$875,"✓") -> 36 | E24: =COUNTIFS('📝 Vocabulary Test'!$D$2:$D$875,"Kelionės",'📝 Vocabulary Test'!$F$2:$F$875,"~?") -> 17 | F24: =COUNTIFS('📝 Vocabulary Test'!$D$2:$D$875,"Kelionės",'📝 Vocabulary Test'!$F$2:$F$875,"✗") -> 16 | G24: =IF(C24=0,"0%",D24/C24) -> 0.52173913
B25: Laisvalaikis | C25: =COUNTIF('📝 Vocabulary Test'!D:D,"Laisvalaikis") -> 64 | D25: =COUNTIFS('📝 Vocabulary Test'!$D$2:$D$875,"Laisvalaikis",'📝 Vocabulary Test'!$F$2:$F$875,"✓") -> 34 | E25: =COUNTIFS('📝 Vocabulary Test'!$D$2:$D$875,"Laisvalaikis",'📝 Vocabulary Test'!$F$2:$F$875,"~?") -> 14 | F25: =COUNTIFS('📝 Vocabulary Test'!$D$2:$D$875,"Laisvalaikis",'📝 Vocabulary Test'!$F$2:$F$875,"✗") -> 16 | G25: =IF(C25=0,"0%",D25/C25) -> 0.53125
B26: Maistas ir gėrimai | C26: =COUNTIF('📝 Vocabulary Test'!D:D,"Maistas ir gėrimai") -> 88 | D26: =COUNTIFS('📝 Vocabulary Test'!$D$2:$D$875,"Maistas ir gėrimai",'📝 Vocabulary Test'!$F$2:$F$875,"✓") -> 63 | E26: =COUNTIFS('📝 Vocabulary Test'!$D$2:$D$875,"Maistas ir gėrimai",'📝 Vocabulary Test'!$F$2:$F$875,"~?") -> 15 | F26: =COUNTIFS('📝 Vocabulary Test'!$D$2:$D$875,"Maistas ir gėrimai",'📝 Vocabulary Test'!$F$2:$F$875,"✗") -> 10 | G26: =IF(C26=0,"0%",D26/C26) -> 0.71590909
B27: Paslaugos | C27: =COUNTIF('📝 Vocabulary Test'!D:D,"Paslaugos") -> 70 | D27: =COUNTIFS('📝 Vocabulary Test'!$D$2:$D$875,"Paslaugos",'📝 Vocabulary Test'!$F$2:$F$875,"✓") -> 45 | E27: =COUNTIFS('📝 Vocabulary Test'!$D$2:$D$875,"Paslaugos",'📝 Vocabulary Test'!$F$2:$F$875,"~?") -> 14 | F27: =COUNTIFS('📝 Vocabulary Test'!D:D,"Paslaugos",'📝 Vocabulary Test'!F:F,"✗") -> 11 | G27: =IF(C27=0,"0%",D27/C27) -> 0.64285714
B28: Prekyba | C28: =COUNTIF('📝 Vocabulary Test'!D:D,"Prekyba") -> 73 | D28: =COUNTIFS('📝 Vocabulary Test'!$D$2:$D$875,"Prekyba",'📝 Vocabulary Test'!$F$2:$F$875,"✓") -> 45 | E28: =COUNTIFS('📝 Vocabulary Test'!$D$2:$D$875,"Prekyba",'📝 Vocabulary Test'!$F$2:$F$875,"~?") -> 15 | F28: =COUNTIFS('📝 Vocabulary Test'!$D$2:$D$875,"Prekyba",'📝 Vocabulary Test'!$F$2:$F$875,"✗") -> 13 | G28: =IF(C28=0,"0%",D28/C28) -> 0.61643836
B29: Santykiai su žmonėmis | C29: =COUNTIF('📝 Vocabulary Test'!D:D,"Santykiai su žmonėmis") -> 78 | D29: =COUNTIFS('📝 Vocabulary Test'!$D$2:$D$875,"Santykiai su žmonėmis",'📝 Vocabulary Test'!$F$2:$F$875,"✓") -> 37 | E29: =COUNTIFS('📝 Vocabulary Test'!$D$2:$D$875,"Santykiai su žmonėmis",'📝 Vocabulary Test'!$F$2:$F$875,"~?") -> 15 | F29: =COUNTIFS('📝 Vocabulary Test'!$D$2:$D$875,"Santykiai su žmonėmis",'📝 Vocabulary Test'!$F$2:$F$875,"✗") -> 26 | G29: =IF(C29=0,"0%",D29/C29) -> 0.47435897
B30: Sveikata ir higiena | C30: =COUNTIF('📝 Vocabulary Test'!D:D,"Sveikata ir higiena") -> 71 | D30: =COUNTIFS('📝 Vocabulary Test'!$D$2:$D$875,"Sveikata ir higiena",'📝 Vocabulary Test'!$F$2:$F$875,"✓") -> 33 | E30: =COUNTIFS('📝 Vocabulary Test'!$D$2:$D$875,"Sveikata ir higiena",'📝 Vocabulary Test'!$F$2:$F$875,"~?") -> 27 | F30: =COUNTIFS('📝 Vocabulary Test'!$D$2:$D$875,"Sveikata ir higiena",'📝 Vocabulary Test'!$F$2:$F$875,"✗") -> 11 | G30: =IF(C30=0,"0%",D30/C30) -> 0.46478873
B31: Švietimas ir mokslas | C31: =COUNTIF('📝 Vocabulary Test'!D:D,"Švietimas ir mokslas") -> 76 | D31: =COUNTIFS('📝 Vocabulary Test'!$D$2:$D$875,"Švietimas ir mokslas",'📝 Vocabulary Test'!$F$2:$F$875,"✓") -> 37 | E31: =COUNTIFS('📝 Vocabulary Test'!$D$2:$D$875,"Švietimas ir mokslas",'📝 Vocabulary Test'!$F$2:$F$875,"~?") -> 10 | F31: =COUNTIFS('📝 Vocabulary Test'!$D$2:$D$875,"Švietimas ir mokslas",'📝 Vocabulary Test'!$F$2:$F$875,"✗") -> 29 | G31: =IF(C31=0,"0%",D31/C31) -> 0.48684211
B36: Knowledge by Tier
B37: Topic | C37: Total | D37: Know (✓) | E37: Unsure (?) | F37: Don't Know (✗) | G37: % Known
B38: Tier 1 - 🔥 MOST IMPORTANT | C38: =COUNTIF('📝 Vocabulary Test'!E:E,"Tier 1") -> 262 | D38: =COUNTIFS('📝 Vocabulary Test'!$E$2:$E$875,"Tier 1",'📝 Vocabulary Test'!$F$2:$F$875,"✓") -> 181 | E38: =COUNTIFS('📝 Vocabulary Test'!$E$2:$E$875,"Tier 1",'📝 Vocabulary Test'!$F$2:$F$875,"~?") -> 58 | F38: =COUNTIFS('📝 Vocabulary Test'!$E$2:$E$875,"Tier 1",'📝 Vocabulary Test'!$F$2:$F$875,"✗") -> 23 | G38: =IF(C38=0,"0%",D38/C38) -> 0.69083969
B39: Tier 2 - 🔸 High Priority | C39: =COUNTIF('📝 Vocabulary Test'!E:E,"Tier 2") -> 346 | D39: =COUNTIFS('📝 Vocabulary Test'!$E$2:$E$875,"Tier 2",'📝 Vocabulary Test'!$F$2:$F$875,"✓") -> 199 | E39: =COUNTIFS('📝 Vocabulary Test'!$E$2:$E$875,"Tier 2",'📝 Vocabulary Test'!$F$2:$F$875,"~?") -> 88 | F39: =COUNTIFS('📝 Vocabulary Test'!$E$2:$E$875,"Tier 2",'📝 Vocabulary Test'!$F$2:$F$875,"✗") -> 59 | G39: =IF(C39=0,"0%",D39/C39) -> 0.57514451
B40: Tier 3 - 🔹 Medium Priority | C40: =COUNTIF('📝 Vocabulary Test'!E:E,"Tier 3") -> 203 | D40: =COUNTIFS('📝 Vocabulary Test'!$E$2:$E$875,"Tier 3",'📝 Vocabulary Test'!$F$2:$F$875,"✓") -> 86 | E40: =COUNTIFS('📝 Vocabulary Test'!$E$2:$E$875,"Tier 3",'📝 Vocabulary Test'!$F$2:$F$875,"~?") -> 40 | F40: =COUNTIFS('📝 Vocabulary Test'!$E$2:$E$875,"Tier 3",'📝 Vocabulary Test'!$F$2:$F$875,"✗") -> 77 | G40: =IF(C40=0,"0%",D40/C40) -> 0.42364532
B41: Tier 4 - ◽ Recognition | C41: =COUNTIF('📝 Vocabulary Test'!E:E,"Tier 4") -> 63 | D41: =COUNTIFS('📝 Vocabulary Test'!$E$2:$E$875,"Tier 4",'📝 Vocabulary Test'!$F$2:$F$875,"✓") -> 18 | E41: =COUNTIFS('📝 Vocabulary Test'!$E$2:$E$875,"Tier 4",'📝 Vocabulary Test'!$F$2:$F$875,"~?") -> 18 | F41: =COUNTIFS('📝 Vocabulary Test'!$E$2:$E$875,"Tier 4",'📝 Vocabulary Test'!$F$2:$F$875,"✗") -> 27 | G41: =IF(C41=0,"0%",D41/C41) -> 0.28571429

Sheet 🚀 Study Priorities
B2: Your Personalised Study Plan
B4: Priority 1: Words You Don't Know (✗) by Topic
B5: These are your main study targets. Start here!
B7: Priority 2: Words You're Unsure About (?) by Topic
B8: Review these to build confidence.
B28: Note: To get your personalized study list, filter the Vocabulary Test sheet:
B29: 1. Go to the "Vocabulary Test" sheet
B30: 2. Click on the header row (row 1)
B31: 3. Enable filters (Data → Filter)
B32: 4. Click the dropdown in "Know It?" column
B33: 5. Select only "✗" or "?" to see words you need to study
